Install python-dotenv solution
user
pip install dotenv
Collecting dotenv
  Downloading dotenv-0.0.5.tar.gz (2.4 kB)
  Preparing metadata (setup.py) ... error
  error: subprocess-exited-with-error
  
  × python setup.py egg_info did not run successfully.
  │ exit code: 1
  ╰─> [63 lines of output]
      WARNING: The wheel package is not available.
        error: subprocess-exited-with-error
      
        × python setup.py egg_info did not run successfully.
        │ exit code: 1
        ╰─> [16 lines of output]
            Traceback (most recent call last):
              File "<string>", line 2, in <module>
              File "<pip-setuptools-caller>", line 14, in <module>
              File "/tmp/pip-wheel-c1wudryi/distribute_efd33a4302df43d6a2689978993c2bb5/setuptools/__init__.py", line 2, in <module>
                from setuptools.extension import Extension, Library
              File "/tmp/pip-wheel-c1wudryi/distribute_efd33a4302df43d6a2689978993c2bb5/setuptools/extension.py", line 5, in <module>
                from setuptools.dist import _get_unpatched
              File "/tmp/pip-wheel-c1wudryi/distribute_efd33a4302df43d6a2689978993c2bb5/setuptools/dist.py", line 7, in <module>
                from setuptools.command.install import install
              File "/tmp/pip-wheel-c1wudryi/distribute_efd33a4302df43d6a2689978993c2bb5/setuptools/command/__init__.py", line 8, in <module>
                from setuptools.command import install_scripts
              File "/tmp/pip-wheel-c1wudryi/distribute_efd33a4302df43d6a2689978993c2bb5/setuptools/command/install_scripts.py", line 3, in <module>
                from pkg_resources import Distribution, PathMetadata, ensure_directory
              File "/tmp/pip-wheel-c1wudryi/distribute_efd33a4302df43d6a2689978993c2bb5/pkg_resources.py", line 1518, in <module>
                register_loader_type(importlib_bootstrap.SourceFileLoader, DefaultProvider)
            AttributeError: module 'importlib._bootstrap' has no attribute 'SourceFileLoader'
            [end of output]
      
        note: This error originates from a subprocess, and is likely not a problem with pip.
      error: metadata-generation-failed
      
      × Encountered error while generating package metadata.
      ╰─> See above for output.
      
      note: This is an issue with the package mentioned above, not pip.
      hint: See above for details.
      Traceback (most recent call last):
        File "/home/jack/Desktop/flasky/flasky/lib/python3.9/site-packages/setuptools/installer.py", line 75, in fetch_build_egg
          subprocess.check_call(cmd)
        File "/home/jack/miniconda3/lib/python3.9/subprocess.py", line 373, in check_call
          raise CalledProcessError(retcode, cmd)
      subprocess.CalledProcessError: Command '['/home/jack/Desktop/flasky/flasky/bin/python3', '-m', 'pip', '--disable-pip-version-check', 'wheel', '--no-deps', '-w', '/tmp/tmpk18d9eer', '--quiet', 'distribute']' returned non-zero exit status 1.
      
      The above exception was the direct cause of the following exception:
      
      Traceback (most recent call last):
        File "<string>", line 2, in <module>
        File "<pip-setuptools-caller>", line 34, in <module>
        File "/tmp/pip-install-iwt6tr0l/dotenv_ccb73504d8c74da58b06c500f16b5b1d/setup.py", line 13, in <module>
          setup(name='dotenv',
        File "/home/jack/Desktop/flasky/flasky/lib/python3.9/site-packages/setuptools/__init__.py", line 152, in setup
          _install_setup_requires(attrs)
        File "/home/jack/Desktop/flasky/flasky/lib/python3.9/site-packages/setuptools/__init__.py", line 147, in _install_setup_requires
          dist.fetch_build_eggs(dist.setup_requires)
        File "/home/jack/Desktop/flasky/flasky/lib/python3.9/site-packages/setuptools/dist.py", line 806, in fetch_build_eggs
          resolved_dists = pkg_resources.working_set.resolve(
        File "/home/jack/Desktop/flasky/flasky/lib/python3.9/site-packages/pkg_resources/__init__.py", line 766, in resolve
          dist = best[req.key] = env.best_match(
        File "/home/jack/Desktop/flasky/flasky/lib/python3.9/site-packages/pkg_resources/__init__.py", line 1051, in best_match
          return self.obtain(req, installer)
        File "/home/jack/Desktop/flasky/flasky/lib/python3.9/site-packages/pkg_resources/__init__.py", line 1063, in obtain
          return installer(requirement)
        File "/home/jack/Desktop/flasky/flasky/lib/python3.9/site-packages/setuptools/dist.py", line 877, in fetch_build_egg
          return fetch_build_egg(self, req)
        File "/home/jack/Desktop/flasky/flasky/lib/python3.9/site-packages/setuptools/installer.py", line 77, in fetch_build_egg
          raise DistutilsError(str(e)) from e
      distutils.errors.DistutilsError: Command '['/home/jack/Desktop/flasky/flasky/bin/python3', '-m', 'pip', '--disable-pip-version-check', 'wheel', '--no-deps', '-w', '/tmp/tmpk18d9eer', '--quiet', 'distribute']' returned non-zero exit status 1.
      [end of output]
  
  note: This error originates from a subprocess, and is likely not a problem with pip.
error: metadata-generation-failed

× Encountered error while generating package metadata.
╰─> See above for output.

note: This is an issue with the package mentioned above, not pip.
hint: See above for details.
(flasky) jack@jack-Desktop:~/Desktop/flasky$ cd flasky/bin
(flasky) jack@jack-Desktop:~/Desktop/flasky/flasky/bin$ ls
activate      activate.fish  flask  pip3    python   python3.9
activate.csh  Activate.ps1   pip    pip3.9  python3
(flasky) jack@jack-Desktop:~/Desktop/flasky/flasky/bin$ 


ChatGPT
The error you encountered is related to the package metadata generation process, which can sometimes be caused by issues with the package itself or conflicts in the environment. Here are some steps you can try to resolve the issue:

1. **Ensure `setuptools` and `wheel` are up to date**:
   ```sh
   pip install --upgrade setuptools wheel
   ```

2. **Install the `python-dotenv` package** instead of `dotenv`, as `python-dotenv` is the more commonly used package for managing environment variables in Python:
   ```sh
   pip install python-dotenv
   ```

3. **Check for conflicts** in your environment. Sometimes, older versions of packages can cause issues. You can create a new virtual environment and try installing the package there.

Here's a step-by-step guide to create a new virtual environment and install `python-dotenv`:

1. **Create a new virtual environment**:
   ```sh
   python3 -m venv newenv
   ```

2. **Activate the virtual environment**:
   ```sh
   source newenv/bin/activate  # On Linux/macOS
   newenv\Scripts\activate     # On Windows
   ```

3. **Upgrade `pip`, `setuptools`, and `wheel`**:
   ```sh
   pip install --upgrade pip setuptools wheel
   ```

4. **Install `python-dotenv`**:
   ```sh
   pip install python-dotenv
   ```

After following these steps, you should have `python-dotenv` installed without encountering the previous error. If you still face issues, there might be deeper conflicts within your environment or specific system-related problems that need further investigation.
user
Traceback (most recent call last):
  File "/home/jack/Desktop/flasky/flasky.py", line 18, in <module>
    from app.models import User, Follow, Role, Permission, Post, Comment
  File "/home/jack/Desktop/flasky/app/models.py", line 4, in <module>
    from itsdangerous import TimedJSONWebSignatureSerializer as Serializer
ImportError: cannot import name 'TimedJSONWebSignatureSerializer' from 'itsdangerous' (/home/jack/Desktop/flasky/flasky/lib/python3.9/site-packages/itsdangerous/__init__.py)

ChatGPT
The error you are encountering indicates that the `TimedJSONWebSignatureSerializer` cannot be imported from the `itsdangerous` package. This might be due to a version mismatch or a deprecated import path in newer versions of the `itsdangerous` package.

To resolve this, you can follow these steps:

1. **Check the version of `itsdangerous`**:
   ```sh
   pip show itsdangerous
   ```

2. **Update the import statement**:
   In newer versions of `itsdangerous`, `TimedJSONWebSignatureSerializer` might have been moved or renamed. If you are using a recent version, try using the updated import statement:

   ```python
   from itsdangerous.serializer import Serializer
   from itsdangerous import URLSafeTimedSerializer as TimedJSONWebSignatureSerializer
   ```

3. **Pin the version of `itsdangerous`**:
   If the above solution does not work, you can pin the version of `itsdangerous` to a known working version. For example:

   ```sh
   pip install itsdangerous==1.1.0
   ```

   You can add this to your `requirements.txt` if you have one.

Here is a complete example of updating your import statements in `models.py`:

```python
# app/models.py
from itsdangerous.serializer import Serializer
from itsdangerous import URLSafeTimedSerializer as TimedJSONWebSignatureSerializer

# Rest of your imports and code
from flask import current_app
from flask_login import UserMixin, AnonymousUserMixin
from . import db
from werkzeug.security import generate_password_hash, check_password_hash

# Your model definitions follow...
```

If you decide to pin the version of `itsdangerous`, make sure to update your `requirements.txt` or install it manually:

```sh
pip install itsdangerous==1.1.0
```

Here is the command to pin the version in `requirements.txt`:
```txt
itsdangerous==1.1.0
```

This should resolve the import error you are encountering.
user
 File "/home/jack/Desktop/flasky/flasky.py", line 20, in <module>
    app = create_app(os.getenv('FLASK_CONFIG') or 'default')
  File "/home/jack/Desktop/flasky/app/__init__.py", line 36, in create_app
    from .main import main as main_blueprint
  File "/home/jack/Desktop/flasky/app/main/__init__.py", line 5, in <module>
    from . import views, errors
  File "/home/jack/Desktop/flasky/app/main/views.py", line 4, in <module>
    from flask_sqlalchemy import get_debug_queries
ImportError: cannot import name 'get_debug_queries' from 'flask_sqlalchemy' (/home/jack/Desktop/flasky/flasky/lib/python3.9/site-packages/flask_sqlalchemy/__init__.py)

ChatGPT
The error you're encountering indicates that `get_debug_queries` cannot be imported from `flask_sqlalchemy`. This function has been deprecated in recent versions of `flask_sqlalchemy`. Instead, you can use the `SQLALCHEMY_RECORD_QUERIES` configuration option along with the `get_debug_queries` method from `SQLAlchemy` directly.

Here are the steps to resolve this issue:

1. **Update your `views.py`**:
   Instead of importing `get_debug_queries` from `flask_sqlalchemy`, import `SQLAlchemy` and use its `get_debug_queries` method.

2. **Ensure `SQLALCHEMY_RECORD_QUERIES` is enabled**:
   Set `SQLALCHEMY_RECORD_QUERIES` to `True` in your Flask app configuration to record the queries.

Here is the updated `views.py` and `__init__.py` with necessary modifications:

### `views.py`:
```python
# app/main/views.py
from flask import render_template, request, current_app
from . import main
from app import db

# Other imports and your view functions

@main.route('/show-debug-queries')
def show_debug_queries():
    if current_app.config['SQLALCHEMY_RECORD_QUERIES']:
        queries = db.get_debug_queries()
        return render_template('debug_queries.html', queries=queries)
    return 'Debug queries not enabled.'
```

### `__init__.py`:
Ensure you have the `SQLALCHEMY_RECORD_QUERIES` configuration option set to `True`:
```python
# app/__init__.py
from flask import Flask
from flask_sqlalchemy import SQLAlchemy
from config import config

db = SQLAlchemy()

def create_app(config_name):
    app = Flask(__name__)
    app.config.from_object(config[config_name])
    config[config_name].init_app(app)

    db.init_app(app)

    # Ensure this configuration is set
    app.config['SQLALCHEMY_RECORD_QUERIES'] = True

    # Import and register blueprints
    from .main import main as main_blueprint
    app.register_blueprint(main_blueprint)

    return app
```

This ensures that `SQLALCHEMY_RECORD_QUERIES` is set to `True`, and you can use `db.get_debug_queries()` to get the debug queries in your views.

### Example Configuration:
If you have a `config.py` file, make sure it looks something like this:
```python
# config.py
import os

class Config:
    SECRET_KEY = os.environ.get('SECRET_KEY') or 'hard to guess string'
    SQLALCHEMY_TRACK_MODIFICATIONS = False
    SQLALCHEMY_RECORD_QUERIES = True  # Ensure this is set

    @staticmethod
    def init_app(app):
        pass

class DevelopmentConfig(Config):
    DEBUG = True
    SQLALCHEMY_DATABASE_URI = os.environ.get('DEV_DATABASE_URL') or \
        'sqlite:///' + os.path.join(basedir, 'data-dev.sqlite')

class TestingConfig(Config):
    TESTING = True
    SQLALCHEMY_DATABASE_URI = os.environ.get('TEST_DATABASE_URL') or \
        'sqlite:///' + os.path.join(basedir, 'data-test.sqlite')

class ProductionConfig(Config):
    SQLALCHEMY_DATABASE_URI = os.environ.get('DATABASE_URL') or \
        'sqlite:///' + os.path.join(basedir, 'data.sqlite')

config = {
    'development': DevelopmentConfig,
    'testing': TestingConfig,
    'production': ProductionConfig,
    'default': DevelopmentConfig
}
```

With these changes, your Flask application should be able to use `get_debug_queries` without any import errors.

